Workbook

Sheet Presupuesto
A1: Código | B1: Partida | C1: Categoría | D1: Cantidad | E1: Coste unitario EUR | F1: Subtotal EUR | G1: IVA 21% | H1: Total EUR | I1: Prioridad | J1: Proveedor/nota
A2: LAB-001 | B2: Kits Arduino compatibles | C2: Electrónica | D2: 24 | E2: 28.5 | F2: =D2*E2 -> 684 | G2: =F2*0.21 -> 143.64 | H2: =F2+G2 -> 827.64 | I2: Alta | J2: Incluye placa, cable y protoboard
A3: LAB-002 | B3: Sensores ultrasónicos | C3: Sensórica | D3: 60 | E3: 3.8 | F3: =D3*E3 -> 228 | G3: =F3*0.21 -> 47.88 | H3: =F3+G3 -> 275.88 | I3: Media | J3: Repuesto para robótica móvil
A4: LAB-003 | B4: Sensores infrarrojos reflectivos | C4: Sensórica | D4: 80 | E4: 2.15 | F4: =D4*E4 -> 172 | G4: =F4*0.21 -> 36.12 | H4: =F4+G4 -> 208.12 | I4: Alta | J4: Seguimiento de línea
A5: LAB-004 | B5: IMU 9 ejes | C5: Sensórica | D5: 18 | E5: 16.9 | F5: =D5*E5 -> 304.2 | G5: =F5*0.21 -> 63.882 | H5: =F5+G5 -> 368.082 | I5: Alta | J5: Orientación y vibraciones
A6: LAB-005 | B6: Encoders magnéticos | C6: Sensórica | D6: 20 | E6: 12.4 | F6: =D6*E6 -> 248 | G6: =F6*0.21 -> 52.08 | H6: =F6+G6 -> 300.08 | I6: Media | J6: Control de velocidad
A7: LAB-006 | B7: Motores DC con reductora | C7: Actuadores | D7: 48 | E7: 9.9 | F7: =D7*E7 -> 475.2 | G7: =F7*0.21 -> 99.792 | H7: =F7+G7 -> 574.992 | I7: Alta | J7: Par medio, eje metálico
A8: LAB-007 | B8: Servomotores estándar | C8: Actuadores | D8: 32 | E8: 7.6 | F8: =D8*E8 -> 243.2 | G8: =F8*0.21 -> 51.072 | H8: =F8+G8 -> 294.272 | I8: Alta | J8: Brazos y mecanismos
A9: LAB-008 | B9: Drivers de motor | C9: Electrónica | D9: 36 | E9: 6.4 | F9: =D9*E9 -> 230.4 | G9: =F9*0.21 -> 48.384 | H9: =F9+G9 -> 278.784 | I9: Media | J9: Puente H doble
A10: LAB-009 | B10: Baterías Li-Ion protegidas | C10: Energía | D10: 40 | E10: 11.75 | F10: =D10*E10 -> 470 | G10: =F10*0.21 -> 98.7 | H10: =F10+G10 -> 568.7 | I10: Alta | J10: Compra con cargador homologado
A11: LAB-010 | B11: Cargadores balanceados | C11: Energía | D11: 8 | E11: 34 | F11: =D11*E11 -> 272 | G11: =F11*0.21 -> 57.12 | H11: =F11+G11 -> 329.12 | I11: Alta | J11: Para packs de laboratorio
A12: LAB-011 | B12: Filamento PLA 1 kg | C12: Fabricación | D12: 20 | E12: 18.9 | F12: =D12*E12 -> 378 | G12: =F12*0.21 -> 79.38 | H12: =F12+G12 -> 457.38 | I12: Media | J12: Colores por equipos
A13: LAB-012 | B13: Filamento PETG 1 kg | C13: Fabricación | D13: 10 | E13: 22.5 | F13: =D13*E13 -> 225 | G13: =F13*0.21 -> 47.25 | H13: =F13+G13 -> 272.25 | I13: Alta | J13: Piezas resistentes
... A41: LAB-040 | B41: Botoneras de emergencia | C41: Seguridad | D41: 6 | E41: 19 | F41: =D41*E41 -> 114 | G41: =F41*0.21 -> 23.94 | H41: =F41+G41 -> 137.94 | I41: Alta | J41: Bancos de pruebas
A42: TOTAL | F42: =SUM(F2:F41) -> 11909.75 | G42: =SUM(G2:G41) -> 2501.0475 | H42: =SUM(H2:H41) -> 14410.798

Sheet Resumen por categoría
A1: Categoría | B1: Número partidas | C1: Subtotal EUR | D1: IVA EUR | E1: Total EUR
A2: Electrónica | B2: =COUNTIF(Presupuesto!C2:C41,A2) -> 4 | C2: =SUMIF(Presupuesto!C2:C41,A2,Presupuesto!F2:F41) -> 1094 | D2: =SUMIF(Presupuesto!C2:C41,A2,Presupuesto!G2:G41) -> 229.74 | E2: =SUMIF(Presupuesto!C2:C41,A2,Presupuesto!H2:H41) -> 1323.74
A3: Sensórica | B3: =COUNTIF(Presupuesto!C2:C41,A3) -> 5 | C3: =SUMIF(Presupuesto!C2:C41,A3,Presupuesto!F2:F41) -> 1240.2 | D3: =SUMIF(Presupuesto!C2:C41,A3,Presupuesto!G2:G41) -> 260.442 | E3: =SUMIF(Presupuesto!C2:C41,A3,Presupuesto!H2:H41) -> 1500.642
A4: Actuadores | B4: =COUNTIF(Presupuesto!C2:C41,A4) -> 3 | C4: =SUMIF(Presupuesto!C2:C41,A4,Presupuesto!F2:F41) -> 886.4 | D4: =SUMIF(Presupuesto!C2:C41,A4,Presupuesto!G2:G41) -> 186.144 | E4: =SUMIF(Presupuesto!C2:C41,A4,Presupuesto!H2:H41) -> 1072.544
A5: Energía | B5: =COUNTIF(Presupuesto!C2:C41,A5) -> 2 | C5: =SUMIF(Presupuesto!C2:C41,A5,Presupuesto!F2:F41) -> 742 | D5: =SUMIF(Presupuesto!C2:C41,A5,Presupuesto!G2:G41) -> 155.82 | E5: =SUMIF(Presupuesto!C2:C41,A5,Presupuesto!H2:H41) -> 897.82
A6: Fabricación | B6: =COUNTIF(Presupuesto!C2:C41,A6) -> 4 | C6: =SUMIF(Presupuesto!C2:C41,A6,Presupuesto!F2:F41) -> 711 | D6: =SUMIF(Presupuesto!C2:C41,A6,Presupuesto!G2:G41) -> 149.31 | E6: =SUMIF(Presupuesto!C2:C41,A6,Presupuesto!H2:H41) -> 860.31
A7: Software | B7: =COUNTIF(Presupuesto!C2:C41,A7) -> 1 | C7: =SUMIF(Presupuesto!C2:C41,A7,Presupuesto!F2:F41) -> 700 | D7: =SUMIF(Presupuesto!C2:C41,A7,Presupuesto!G2:G41) -> 147 | E7: =SUMIF(Presupuesto!C2:C41,A7,Presupuesto!H2:H41) -> 847
A8: Redes | B8: =COUNTIF(Presupuesto!C2:C41,A8) -> 4 | C8: =SUMIF(Presupuesto!C2:C41,A8,Presupuesto!F2:F41) -> 1785 | D8: =SUMIF(Presupuesto!C2:C41,A8,Presupuesto!G2:G41) -> 374.85 | E8: =SUMIF(Presupuesto!C2:C41,A8,Presupuesto!H2:H41) -> 2159.85
A9: Computación | B9: =COUNTIF(Presupuesto!C2:C41,A9) -> 2 | C9: =SUMIF(Presupuesto!C2:C41,A9,Presupuesto!F2:F41) -> 1281.6 | D9: =SUMIF(Presupuesto!C2:C41,A9,Presupuesto!G2:G41) -> 269.136 | E9: =SUMIF(Presupuesto!C2:C41,A9,Presupuesto!H2:H41) -> 1550.736
A10: Instrumentación | B10: =COUNTIF(Presupuesto!C2:C41,A10) -> 3 | C10: =SUMIF(Presupuesto!C2:C41,A10,Presupuesto!F2:F41) -> 1910 | D10: =SUMIF(Presupuesto!C2:C41,A10,Presupuesto!G2:G41) -> 401.1 | E10: =SUMIF(Presupuesto!C2:C41,A10,Presupuesto!H2:H41) -> 2311.1
A11: Seguridad | B11: =COUNTIF(Presupuesto!C2:C41,A11) -> 4 | C11: =SUMIF(Presupuesto!C2:C41,A11,Presupuesto!F2:F41) -> 431 | D11: =SUMIF(Presupuesto!C2:C41,A11,Presupuesto!G2:G41) -> 90.51 | E11: =SUMIF(Presupuesto!C2:C41,A11,Presupuesto!H2:H41) -> 521.51
A12: Mobiliario | B12: =COUNTIF(Presupuesto!C2:C41,A12) -> 2 | C12: =SUMIF(Presupuesto!C2:C41,A12,Presupuesto!F2:F41) -> 511 | D12: =SUMIF(Presupuesto!C2:C41,A12,Presupuesto!G2:G41) -> 107.31 | E12: =SUMIF(Presupuesto!C2:C41,A12,Presupuesto!H2:H41) -> 618.31
A13: Fungible | B13: =COUNTIF(Presupuesto!C2:C41,A13) -> 6 | C13: =SUMIF(Presupuesto!C2:C41,A13,Presupuesto!F2:F41) -> 617.55 | D13: =SUMIF(Presupuesto!C2:C41,A13,Presupuesto!G2:G41) -> 129.6855 | E13: =SUMIF(Presupuesto!C2:C41,A13,Presupuesto!H2:H41) -> 747.2355
A14: TOTAL | B14: =SUM(B2:B13) -> 40 | C14: =SUM(C2:C13) -> 11909.75 | D14: =SUM(D2:D13) -> 2501.0475 | E14: =SUM(E2:E13) -> 14410.798

Sheet Cronograma
A1: Mes | B1: Actividad | C1: Coste previsto EUR | D1: Responsable | E1: Estado | F1: Riesgo
A2: Septiembre | B2: Compra de electrónica básica y fungibles | C2: 1850 | D2: Coordinador de laboratorio | E2: Planificado | F2: Bajo
A3: Septiembre | B3: Revisión de seguridad y EPI | C3: 420 | D3: Técnico de prevención | E3: Planificado | F3: Bajo
A4: Octubre | B4: Fabricación y montaje de prototipos | C4: 760 | D4: Técnico de taller | E4: Pendiente | F4: Medio
A5: Octubre | B5: Puesta a punto de impresoras 3D | C5: 310 | D5: Taller | E5: Pendiente | F5: Medio
A6: Noviembre | B6: Renovación de red docente | C6: 1640 | D6: Profesor de Redes | E6: Pendiente | F6: Medio
A7: Noviembre | B7: Configuración de gateways industriales | C7: 860 | D7: Profesor de Automatización | E7: Pendiente | F7: Alto
A8: Diciembre | B8: Licencias software y reposición | C8: 700 | D8: Administración | E8: Pendiente | F8: Bajo
A9: Enero | B9: Inventario intermedio | C9: 0 | D9: Secretaría técnica | E9: Pendiente | F9: Bajo
A10: Febrero | B10: Reposición por roturas de primer semestre | C10: 500 | D10: Coordinador de laboratorio | E10: Reserva | F10: Medio
A11: Marzo | B11: Compra de instrumentación complementaria | C11: 980 | D11: Departamento | E11: Reserva | F11: Medio
A12: Abril | B12: Auditoría de uso y calibración | C12: 220 | D12: Técnico de laboratorio | E12: Reserva | F12: Bajo
A13: Mayo | B13: Preparación demostraciones finales | C13: 450 | D13: Profesores responsables | E13: Reserva | F13: Medio

Sheet Proveedores
A1: Proveedor | B1: Tipo | C1: Plazo días | D1: Condiciones | E1: Contacto ficticio | F1: Valoración 1-5
A2: Proveedor Técnico 01 | B2: Sensórica | C2: 5 | D2: Pago a 30 días | E2: compras01@ejemplo.edu | F2: 4
A3: Proveedor Técnico 02 | B3: Actuadores | C3: 7 | D3: Transferencia anticipada | E3: compras02@ejemplo.edu | F3: 5
A4: Proveedor Técnico 03 | B4: Energía | C4: 9 | D4: Pago a 30 días | E4: compras03@ejemplo.edu | F4: 3
A5: Proveedor Técnico 04 | B5: Fabricación | C5: 11 | D5: Transferencia anticipada | E5: compras04@ejemplo.edu | F5: 4
A6: Proveedor Técnico 05 | B6: Software | C6: 13 | D6: Pago a 30 días | E6: compras05@ejemplo.edu | F6: 5
A7: Proveedor Técnico 06 | B7: Redes | C7: 15 | D7: Transferencia anticipada | E7: compras06@ejemplo.edu | F7: 3
A8: Proveedor Técnico 07 | B8: Computación | C8: 17 | D8: Pago a 30 días | E8: compras07@ejemplo.edu | F8: 4
A9: Proveedor Técnico 08 | B9: Instrumentación | C9: 19 | D9: Transferencia anticipada | E9: compras08@ejemplo.edu | F9: 5
A10: Proveedor Técnico 09 | B10: Seguridad | C10: 3 | D10: Pago a 30 días | E10: compras09@ejemplo.edu | F10: 3
A11: Proveedor Técnico 10 | B11: Mobiliario | C11: 5 | D11: Transferencia anticipada | E11: compras10@ejemplo.edu | F11: 4
A12: Proveedor Técnico 11 | B12: Fungible | C12: 7 | D12: Pago a 30 días | E12: compras11@ejemplo.edu | F12: 5
A13: Proveedor Técnico 12 | B13: Electrónica | C13: 9 | D13: Transferencia anticipada | E13: compras12@ejemplo.edu | F13: 3
... A21: Proveedor Técnico 20 | B21: Instrumentación | C21: 7 | D21: Transferencia anticipada | E21: compras20@ejemplo.edu | F21: 5

Sheet Inventario
A1: Ubicación | B1: Equipo | C1: Unidades actuales | D1: Unidades mínimas | E1: Estado | F1: Última revisión | G1: Observaciones
A2: Armario 2 | B2: Sensores ultrasónicos | C2: 4 | D2: 3 | E2: Correcto | F2: 2026-02-04
A3: Armario 3 | B3: Sensores infrarrojos reflectivos | C3: 7 | D3: 4 | E3: Correcto | F3: 2026-03-07
A4: Armario 4 | B4: IMU 9 ejes | C4: 10 | D4: 5 | E4: Correcto | F4: 2026-04-10
A5: Armario 5 | B5: Encoders magnéticos | C5: 13 | D5: 6 | E5: Correcto | F5: 2026-05-13
A6: Armario 6 | B6: Motores DC con reductora | C6: 16 | D6: 7 | E6: Revisar | F6: 2026-01-16
A7: Armario 1 | B7: Servomotores estándar | C7: 19 | D7: 8 | E7: Correcto | F7: 2026-02-19
A8: Armario 2 | B8: Drivers de motor | C8: 22 | D8: 9 | E8: Correcto | F8: 2026-03-22 | G8: Rotular
A9: Armario 3 | B9: Baterías Li-Ion protegidas | C9: 25 | D9: 2 | E9: Correcto | F9: 2026-04-25
A10: Armario 4 | B10: Cargadores balanceados | C10: 28 | D10: 3 | E10: Correcto | F10: 2026-05-28
A11: Armario 5 | B11: Filamento PLA 1 kg | C11: 3 | D11: 4 | E11: Revisar | F11: 2026-01-03
A12: Armario 6 | B12: Filamento PETG 1 kg | C12: 6 | D12: 5 | E12: Correcto | F12: 2026-02-06
A13: Armario 1 | B13: Boquillas impresora 3D | C13: 9 | D13: 6 | E13: Correcto | F13: 2026-03-09
A14: Armario 2 | B14: Licencias simulador educativo | C14: 12 | D14: 7 | E14: Correcto | F14: 2026-04-12
A15: Armario 3 | B15: Switch gestionable 8 puertos | C15: 15 | D15: 8 | E15: Correcto | F15: 2026-05-15 | G15: Rotular
A16: Armario 4 | B16: Puntos de acceso WiFi 6 | C16: 18 | D16: 9 | E16: Revisar | F16: 2026-01-18
A17: Armario 5 | B17: Raspberry Pi 5 | C17: 21 | D17: 2 | E17: Correcto | F17: 2026-02-21
A18: Armario 6 | B18: Tarjetas microSD 64 GB | C18: 24 | D18: 3 | E18: Correcto | F18: 2026-03-24
A19: Armario 1 | B19: Multímetros digitales | C19: 27 | D19: 4 | E19: Correcto | F19: 2026-04-27
A20: Armario 2 | B20: Osciloscopio USB | C20: 2 | D20: 5 | E20: Correcto | F20: 2026-05-02
A21: Armario 3 | B21: Fuentes de alimentación regulables | C21: 5 | D21: 6 | E21: Revisar | F21: 2026-01-05
A22: Armario 4 | B22: Gafas de seguridad | C22: 8 | D22: 7 | E22: Correcto | F22: 2026-02-08 | G22: Rotular
A23: Armario 5 | B23: Guantes antiestáticos | C23: 11 | D23: 8 | E23: Correcto | F23: 2026-03-11
A24: Armario 6 | B24: Extintor CO2 revisión | C24: 14 | D24: 9 | E24: Correcto | F24: 2026-04-14
A25: Armario 1 | B25: Carros de almacenamiento | C25: 17 | D25: 2 | E25: Correcto | F25: 2026-05-17
A26: Armario 2 | B26: Cajas organizadoras | C26: 20 | D26: 3 | E26: Revisar | F26: 2026-01-20
A27: Armario 3 | B27: Cables Dupont surtidos | C27: 23 | D27: 4 | E27: Correcto | F27: 2026-02-23
A28: Armario 4 | B28: Estaño sin plomo | C28: 26 | D28: 5 | E28: Correcto | F28: 2026-03-26
A29: Armario 5 | B29: Tubos termorretráctiles | C29: 1 | D29: 6 | E29: Correcto | F29: 2026-04-01 | G29: Rotular
A30: Armario 6 | B30: Conectores JST surtidos | C30: 4 | D30: 7 | E30: Correcto | F30: 2026-05-04
A31: Armario 1 | B31: Placas prototipo perforadas | C31: 7 | D31: 8 | E31: Revisar | F31: 2026-01-07
A32: Armario 2 | B32: Tornillería M3 surtida | C32: 10 | D32: 9 | E32: Correcto | F32: 2026-02-10
A33: Armario 3 | B33: Ruedas de goma 65 mm | C33: 13 | D33: 2 | E33: Correcto | F33: 2026-03-13
A34: Armario 4 | B34: Rodamientos pequeños | C34: 16 | D34: 3 | E34: Correcto | F34: 2026-04-16
A35: Armario 5 | B35: Módulos relé optoaislados | C35: 19 | D35: 4 | E35: Correcto | F35: 2026-05-19
A36: Armario 6 | B36: Conversores USB-RS485 | C36: 22 | D36: 5 | E36: Revisar | F36: 2026-01-22 | G36: Rotular
A37: Armario 1 | B37: Gateway MQTT industrial | C37: 25 | D37: 6 | E37: Correcto | F37: 2026-02-25
A38: Armario 2 | B38: Sensores de temperatura PT100 | C38: 28 | D38: 7 | E38: Correcto | F38: 2026-03-28
A39: Armario 3 | B39: Amplificadores instrumentación | C39: 3 | D39: 8 | E39: Correcto | F39: 2026-04-03
A40: Armario 4 | B40: Botoneras de emergencia | C40: 6 | D40: 9 | E40: Correcto | F40: 2026-05-06
...
